Workbook

Sheet # Customers
A1: COHORT | B1: 0 | C1: 1 | D1: 2 | E1: 3 | F1: 4 | G1: 5 | H1: 6 | I1: 7 | J1: 8 | K1: 9 | L1: 10 | M1: 11 | N1: 12 | O1: 13 | P1: 14 | Q1: 15 | R1: 16 | S1: 17 | T1: 18 | U1: 19 | V1: 20 | W1: 21 | X1: 22 | Y1: 23 | Z1: 24 | AA1: 25 | AB1: 26 | AC1: 27 | AD1: 28 | AE1: 29 | AF1: 30 | AG1: 31 | AH1: 32 | AI1: 33 | AJ1: 34 | AK1: 35 | AL1: 36 | AM1: 37 | AN1: 38 | AO1: 39 | AP1: 40 | AQ1: 41
A2: Q3-2012 | B2: 13643 | C2: 3483 | D2: 3411 | E2: 5177 | F2: 4501 | G2: 3450 | H2: 3610 | I2: 5308 | J2: 4360 | K2: 3475 | L2: 3439 | M2: 5446 | N2: 4579 | O2: 3647 | P2: 3607 | Q2: 5651 | R2: 4447 | S2: 3419 | T2: 3310 | U2: 5410 | V2: 4205 | W2: 2993 | X2: 3124 | Y2: 5369 | Z2: 3918 | AA2: 2185 | AB2: 2348 | AC2: 3171 | AD2: 2677 | AE2: 1847 | AF2: 1745 | AG2: 2938 | AH2: 2295 | AI2: 1499 | AJ2: 1902 | AK2: 2910 | AL2: 2125 | AM2: 1488 | AN2: 2059 | AO2: 2910 | AP2: 2166 | AQ2: 1589
A3: Q4-2012 | B3: 8425 | C3: 1869 | D3: 2742 | E3: 2353 | F3: 1923 | G3: 2064 | H3: 2893 | I3: 2376 | J3: 2070 | K3: 1946 | L3: 2919 | M3: 2425 | N3: 2097 | O3: 1986 | P3: 3080 | Q3: 2462 | R3: 1939 | S3: 1851 | T3: 2929 | U3: 2265 | V3: 1797 | W3: 1689 | X3: 3015 | Y3: 2208 | Z3: 1252 | AA3: 1209 | AB3: 1641 | AC3: 1396 | AD3: 976 | AE3: 1001 | AF3: 1511 | AG3: 1241 | AH3: 848 | AI3: 1003 | AJ3: 1559 | AK3: 1171 | AL3: 777 | AM3: 1093 | AN3: 1564 | AO3: 1196 | AP3: 890
A4: Q1-2013 | B4: 6697 | C4: 2003 | D4: 1658 | E4: 1266 | F4: 1331 | G4: 2059 | H4: 1631 | I4: 1283 | J4: 1278 | K4: 2135 | L4: 1792 | M4: 1361 | N4: 1304 | O4: 2188 | P4: 1662 | Q4: 1211 | R4: 1271 | S4: 2102 | T4: 1608 | U4: 1155 | V4: 1200 | W4: 2124 | X4: 1500 | Y4: 801 | Z4: 877 | AA4: 1246 | AB4: 1038 | AC4: 666 | AD4: 666 | AE4: 1129 | AF4: 868 | AG4: 535 | AH4: 736 | AI4: 1145 | AJ4: 842 | AK4: 525 | AL4: 755 | AM4: 1093 | AN4: 869 | AO4: 592
A5: Q2-2013 | B5: 9301 | C5: 1925 | D5: 1371 | E5: 1490 | F5: 2454 | G5: 1954 | H5: 1379 | I5: 1444 | J5: 2515 | K5: 1987 | L5: 1500 | M5: 1493 | N5: 2595 | O5: 1914 | P5: 1295 | Q5: 1383 | R5: 2496 | S5: 1874 | T5: 1274 | U5: 1331 | V5: 2671 | W5: 1777 | X5: 908 | Y5: 959 | Z5: 1458 | AA5: 1199 | AB5: 728 | AC5: 743 | AD5: 1347 | AE5: 1040 | AF5: 622 | AG5: 804 | AH5: 1320 | AI5: 995 | AJ5: 575 | AK5: 877 | AL5: 1348 | AM5: 991 | AN5: 651
A6: Q3-2013 | B6: 5719 | C6: 737 | D6: 779 | E6: 1381 | F6: 1060 | G6: 758 | H6: 770 | I6: 1276 | J6: 1058 | K6: 814 | L6: 799 | M6: 1395 | N6: 1005 | O6: 701 | P6: 699 | Q6: 1295 | R6: 1047 | S6: 656 | T6: 702 | U6: 1342 | V6: 924 | W6: 471 | X6: 489 | Y6: 786 | Z6: 594 | AA6: 416 | AB6: 406 | AC6: 709 | AD6: 527 | AE6: 285 | AF6: 397 | AG6: 706 | AH6: 542 | AI6: 291 | AJ6: 472 | AK6: 675 | AL6: 490 | AM6: 338
A7: Q4-2013 | B7: 3382 | C7: 417 | D7: 670 | E7: 558 | F7: 442 | G7: 407 | H7: 700 | I7: 577 | J7: 471 | K7: 418 | L7: 721 | M7: 572 | N7: 470 | O7: 376 | P7: 695 | Q7: 524 | R7: 370 | S7: 375 | T7: 704 | U7: 483 | V7: 263 | W7: 256 | X7: 415 | Y7: 294 | Z7: 197 | AA7: 210 | AB7: 329 | AC7: 269 | AD7: 186 | AE7: 199 | AF7: 345 | AG7: 269 | AH7: 164 | AI7: 233 | AJ7: 398 | AK7: 281 | AL7: 187
A8: Q1-2014 | B8: 3059 | C8: 571 | D8: 416 | E8: 324 | F8: 323 | G8: 553 | H8: 473 | I8: 346 | J8: 361 | K8: 631 | L8: 451 | M8: 338 | N8: 331 | O8: 598 | P8: 418 | Q8: 321 | R8: 307 | S8: 586 | T8: 391 | U8: 201 | V8: 209 | W8: 309 | X8: 240 | Y8: 190 | Z8: 168 | AA8: 268 | AB8: 238 | AC8: 153 | AD8: 194 | AE8: 279 | AF8: 221 | AG8: 155 | AH8: 196 | AI8: 262 | AJ8: 231 | AK8: 154
A9: Q2-2014 | B9: 5172 | C9: 632 | D9: 476 | E9: 438 | F9: 838 | G9: 667 | H9: 493 | I9: 518 | J9: 935 | K9: 639 | L9: 445 | M9: 431 | N9: 835 | O9: 650 | P9: 383 | Q9: 413 | R9: 926 | S9: 610 | T9: 265 | U9: 296 | V9: 509 | W9: 401 | X9: 240 | Y9: 251 | Z9: 443 | AA9: 330 | AB9: 190 | AC9: 240 | AD9: 422 | AE9: 299 | AF9: 182 | AG9: 254 | AH9: 467 | AI9: 321 | AJ9: 208
A10: Q3-2014 | B10: 3074 | C10: 249 | D10: 241 | E10: 470 | F10: 365 | G10: 255 | H10: 249 | I10: 487 | J10: 341 | K10: 240 | L10: 233 | M10: 497 | N10: 341 | O10: 238 | P10: 207 | Q10: 417 | R10: 333 | S10: 167 | T10: 141 | U10: 271 | V10: 206 | W10: 120 | X10: 142 | Y10: 242 | Z10: 193 | AA10: 112 | AB10: 130 | AC10: 236 | AD10: 169 | AE10: 115 | AF10: 158 | AG10: 235 | AH10: 176 | AI10: 128
A11: Q4-2014 | B11: 1988 | C11: 182 | D11: 264 | E11: 202 | F11: 193 | G11: 153 | H11: 303 | I11: 225 | J11: 149 | K11: 152 | L11: 289 | M11: 222 | N11: 163 | O11: 144 | P11: 315 | Q11: 200 | R11: 113 | S11: 122 | T11: 121 | U11: 117 | V11: 75 | W11: 54 | X11: 125 | Y11: 108 | Z11: 77 | AA11: 67 | AB11: 124 | AC11: 118 | AD11: 71 | AE11: 81 | AF11: 123 | AG11: 104 | AH11: 67
A12: Q1-2015 | B12: 1747 | C12: 233 | D12: 176 | E12: 135 | F12: 131 | G12: 229 | H12: 178 | I12: 119 | J12: 133 | K12: 251 | L12: 167 | M12: 143 | N12: 109 | O12: 265 | P12: 156 | Q12: 84 | R12: 92 | S12: 121 | T12: 105 | U12: 71 | V12: 71 | W12: 98 | X12: 87 | Y12: 65 | Z12: 67 | AA12: 133 | AB12: 84 | AC12: 42 | AD12: 70 | AE12: 111 | AF12: 84 | AG12: 63
A13: Q2-2015 | B13: 3402 | C13: 319 | D13: 242 | E13: 230 | F13: 446 | G13: 320 | H13: 180 | I13: 206 | J13: 433 | K13: 300 | L13: 179 | M13: 201 | N13: 435 | O13: 279 | P13: 135 | Q13: 126 | R13: 255 | S13: 167 | T13: 95 | U13: 97 | V13: 210 | W13: 184 | X13: 89 | Y13: 119 | Z13: 214 | AA13: 148 | AB13: 72 | AC13: 124 | AD13: 206 | AE13: 151 | AF13: 105
A14: Q3-2015 | B14: 2295 | C14: 150 | D14: 137 | E14: 274 | F14: 219 | G14: 134 | H14: 147 | I14: 284 | J14: 210 | K14: 124 | L14: 140 | M14: 279 | N14: 175 | O14: 81 | P14: 70 | Q14: 140 | R14: 94 | S14: 79 | T14: 65 | U14: 116 | V14: 102 | W14: 60 | X14: 72 | Y14: 124 | Z14: 106 | AA14: 73 | AB14: 66 | AC14: 133 | AD14: 83 | AE14: 75
A15: Q4-2015 | B15: 1384 | C15: 77 | D15: 142 | E15: 107 | F15: 100 | G15: 93 | H15: 148 | I15: 116 | J15: 83 | K15: 74 | L15: 158 | M15: 114 | N15: 53 | O15: 57 | P15: 81 | Q15: 54 | R15: 48 | S15: 32 | T15: 58 | U15: 44 | V15: 26 | W15: 56 | X15: 53 | Y15: 57 | Z15: 45 | AA15: 45 | AB15: 70 | AC15: 54 | AD15: 36
A16: Q1-2016 | B16: 1295 | C16: 148 | D16: 100 | E16: 63 | F16: 68 | G16: 146 | H16: 111 | I16: 52 | J16: 81 | K16: 134 | L16: 106 | M16: 42 | N16: 45 | O16: 79 | P16: 53 | Q16: 45 | R16: 34 | S16: 60 | T16: 56 | U16: 25 | V16: 42 | W16: 66 | X16: 47 | Y16: 17 | Z16: 32 | AA16: 68 | AB16: 50 | AC16: 27
A17: Q2-2016 | B17: 2563 | C17: 226 | D17: 92 | E17: 118 | F17: 252 | G17: 160 | H17: 120 | I17: 97 | J17: 269 | K17: 165 | L17: 88 | M17: 77 | N17: 128 | O17: 126 | P17: 51 | Q17: 75 | R17: 122 | S17: 91 | T17: 46 | U17: 55 | V17: 124 | W17: 78 | X17: 40 | Y17: 67 | Z17: 133 | AA17: 72 | AB17: 54
A18: Q3-2016 | B18: 1585 | C18: 67 | D18: 57 | E18: 138 | F18: 94 | G18: 62 | H18: 57 | I18: 157 | J18: 89 | K18: 42 | L18: 39 | M18: 60 | N18: 57 | O18: 36 | P18: 40 | Q18: 75 | R18: 50 | S18: 26 | T18: 27 | U18: 70 | V18: 63 | W18: 24 | X18: 37 | Y18: 67 | Z18: 47 | AA18: 33
A19: Q4-2016 | B19: 949 | C19: 37 | D19: 73 | E19: 59 | F19: 49 | G19: 37 | H19: 91 | I19: 49 | J19: 29 | K19: 28 | L19: 41 | M19: 29 | N19: 14 | O19: 29 | P19: 26 | Q19: 18 | R19: 14 | S19: 14 | T19: 33 | U19: 26 | V19: 16 | W19: 20 | X19: 26 | Y19: 21 | Z19: 17
A20: Q1-2017 | B20: 886 | C20: 82 | D20: 50 | E20: 42 | F20: 37 | G20: 69 | H20: 65 | I20: 25 | J20: 25 | K20: 46 | L20: 32 | M20: 15 | N20: 23 | O20: 33 | P20: 18 | Q20: 16 | R20: 19 | S20: 35 | T20: 41 | U20: 21 | V20: 16 | W20: 38 | X20: 15 | Y20: 15
A21: Q2-2017 | B21: 1952 | C21: 106 | D21: 69 | E21: 74 | F21: 159 | G21: 93 | H21: 43 | I21: 43 | J21: 82 | K21: 77 | L21: 38 | M21: 38 | N21: 81 | O21: 35 | P21: 32 | Q21: 34 | R21: 82 | S21: 32 | T21: 30 | U21: 48 | V21: 68 | W21: 40 | X21: 24
A22: Q3-2017 | B22: 1228 | C22: 37 | D22: 39 | E22: 75 | F22: 50 | G22: 26 | H22: 29 | I22: 49 | J22: 42 | K22: 27 | L22: 24 | M22: 43 | N22: 33 | O22: 20 | P22: 34 | Q22: 40 | R22: 40 | S22: 18 | T22: 25 | U22: 37 | V22: 36 | W22: 15
A23: Q4-2017 | B23: 723 | C23: 17 | D23: 59 | E23: 38 | F23: 12 | G23: 23 | H23: 30 | I23: 33 | J23: 18 | K23: 17 | L23: 30 | M23: 20 | N23: 8 | O23: 15 | P23: 35 | Q23: 19 | R23: 13 | S23: 18 | T23: 26 | U23: 16 | V23: 14
A24: Q1-2018 | B24: 734 | C24: 54 | D24: 40 | E24: 22 | F24: 15 | G24: 20 | H24: 25 | I24: 12 | J24: 15 | K24: 23 | L24: 17 | M24: 6 | N24: 19 | O24: 25 | P24: 18 | Q24: 10 | R24: 13 | S24: 24 | T24: 11 | U24: 9
A25: Q2-2018 | B25: 1691 | C25: 82 | D25: 45 | E25: 44 | F25: 54 | G25: 41 | H25: 27 | I25: 31 | J25: 66 | K25: 42 | L25: 14 | M25: 23 | N25: 54 | O25: 30 | P25: 23 | Q25: 30 | R25: 56 | S25: 40 | T25: 22
A26: Q3-2018 | B26: 873 | C26: 16 | D26: 29 | E26: 36 | F26: 22 | G26: 19 | H26: 12 | I26: 25 | J26: 33 | K26: 17 | L26: 11 | M26: 36 | N26: 28 | O26: 13 | P26: 21 | Q26: 26 | R26: 30 | S26: 15
A27: Q4-2018 | B27: 419 | C27: 7 | D27: 12 | E27: 10 | F27: 9 | G27: 4 | H27: 11 | I27: 9 | J27: 2 | K27: 5 | L27: 11 | M27: 7 | N27: 5 | O27: 6 | P27: 15 | Q27: 15 | R27: 4
A28: Q1-2019 | B28: 423 | C28: 10 | D28: 11 | E28: 7 | F28: 7 | G28: 7 | H28: 11 | I28: 7 | J28: 9 | K28: 13 | L28: 9 | M28: 6 | N28: 9 | O28: 9 | P28: 6 | Q28: 10
A29: Q2-2019 | B29: 652 | C29: 26 | D29: 4 | E29: 9 | F29: 19 | G29: 14 | H29: 10 | I29: 13 | J29: 23 | K29: 8 | L29: 7 | M29: 12 | N29: 17 | O29: 11 | P29: 6
A30: Q3-2019 | B30: 515 | C30: 6 | D30: 14 | E30: 11 | F30: 9 | G30: 7 | H30: 6 | I30: 18 | J30: 5 | K30: 1 | L30: 8 | M30: 7 | N30: 13 | O30: 9
A31: Q4-2019 | B31: 308 | C31: 9 | D31: 10 | E31: 4 | F31: 4 | G31: 7 | H31: 6 | I31: 7 | J31: 7 | K31: 7 | L31: 9 | M31: 6 | N31: 4
A32: Q1-2020 | B32: 304 | C32: 10 | D32: 3 | E32: 7 | F32: 5 | G32: 6 | H32: 6 | I32: 8 | J32: 3 | K32: 6 | L32: 5 | M32: 2
A33: Q2-2020 | B33: 551 | C33: 16 | D33: 7 | E33: 10 | F33: 13 | G33: 11 | H33: 7 | I33: 9 | J33: 21 | K33: 11 | L33: 2
A34: Q3-2020 | B34: 408 | C34: 6 | D34: 3 | E34: 11 | F34: 8 | G34: 4 | H34: 9 | I34: 11 | J34: 7 | K34: 5
A35: Q4-2020 | B35: 237 | C35: 2 | D35: 4 | E35: 5 | F35: 6 | G35: 3 | H35: 7 | I35: 9 | J35: 5
A36: Q1-2021 | B36: 278 | C36: 9 | D36: 5 | E36: 3 | F36: 6 | G36: 4 | H36: 5 | I36: 5
A37: Q2-2021 | B37: 518 | C37: 10 | D37: 9 | E37: 12 | F37: 10 | G37: 9 | H37: 7
A38: Q3-2021 | B38: 331 | C38: 5 | D38: 6 | E38: 11 | F38: 6 | G38: 3
A39: Q4-2021 | B39: 213 | C39: 2 | D39: 2 | E39: 2 | F39: 5
A40: Q1-2022 | B40: 302 | C40: 7 | D40: 6 | E40: 1
...

Sheet % Customers
A1: COHORT | B1: 0 | C1: 1 | D1: 2 | E1: 3 | F1: 4 | G1: 5 | H1: 6 | I1: 7 | J1: 8 | K1: 9 | L1: 10 | M1: 11 | N1: 12 | O1: 13 | P1: 14 | Q1: 15 | R1: 16 | S1: 17 | T1: 18 | U1: 19 | V1: 20 | W1: 21 | X1: 22 | Y1: 23 | Z1: 24 | AA1: 25 | AB1: 26 | AC1: 27 | AD1: 28 | AE1: 29 | AF1: 30 | AG1: 31 | AH1: 32 | AI1: 33 | AJ1: 34 | AK1: 35 | AL1: 36 | AM1: 37 | AN1: 38 | AO1: 39 | AP1: 40 | AQ1: 41
A2: Q3-2012 | B2: 13643 | C2: ='# Customers'!C2/'# Customers'!$B2 -> 0.25529576 | D2: ='# Customers'!D2/'# Customers'!$B2 -> 0.25001832 | E2: ='# Customers'!E2/'# Customers'!$B2 -> 0.379462 | F2: ='# Customers'!F2/'# Customers'!$B2 -> 0.32991278 | G2: ='# Customers'!G2/'# Customers'!$B2 -> 0.25287693 | H2: ='# Customers'!H2/'# Customers'!$B2 -> 0.26460456 | I2: ='# Customers'!I2/'# Customers'!$B2 -> 0.38906399 | J2: ='# Customers'!J2/'# Customers'!$B2 -> 0.31957781 | ... AQ2: ='# Customers'!AQ2/'# Customers'!$B2 -> 0.11646998
A3: Q4-2012 | B3: 8425 | C3: ='# Customers'!C3/'# Customers'!$B3 -> 0.22183976 | D3: ='# Customers'!D3/'# Customers'!$B3 -> 0.32545994 | E3: ='# Customers'!E3/'# Customers'!$B3 -> 0.27928783 | F3: ='# Customers'!F3/'# Customers'!$B3 -> 0.22824926 | G3: ='# Customers'!G3/'# Customers'!$B3 -> 0.24498516 | H3: ='# Customers'!H3/'# Customers'!$B3 -> 0.34338279 | I3: ='# Customers'!I3/'# Customers'!$B3 -> 0.2820178 | J3: ='# Customers'!J3/'# Customers'!$B3 -> 0.24569733 | ... AP3: ='# Customers'!AP3/'# Customers'!$B3 -> 0.10563798
A4: Q1-2013 | B4: 6697 | C4: ='# Customers'!C4/'# Customers'!$B4 -> 0.29908914 | D4: ='# Customers'!D4/'# Customers'!$B4 -> 0.24757354 | E4: ='# Customers'!E4/'# Customers'!$B4 -> 0.18903987 | F4: ='# Customers'!F4/'# Customers'!$B4 -> 0.19874571 | G4: ='# Customers'!G4/'# Customers'!$B4 -> 0.3074511 | H4: ='# Customers'!H4/'# Customers'!$B4 -> 0.24354188 | I4: ='# Customers'!I4/'# Customers'!$B4 -> 0.19157832 | J4: ='# Customers'!J4/'# Customers'!$B4 -> 0.19083172 | ... AO4: ='# Customers'!AO4/'# Customers'!$B4 -> 0.08839779
A5: Q2-2013 | B5: 9301 | C5: ='# Customers'!C5/'# Customers'!$B5 -> 0.20696699 | D5: ='# Customers'!D5/'# Customers'!$B5 -> 0.1474035 | E5: ='# Customers'!E5/'# Customers'!$B5 -> 0.16019783 | F5: ='# Customers'!F5/'# Customers'!$B5 -> 0.2638426 | G5: ='# Customers'!G5/'# Customers'!$B5 -> 0.21008494 | H5: ='# Customers'!H5/'# Customers'!$B5 -> 0.14826363 | I5: ='# Customers'!I5/'# Customers'!$B5 -> 0.15525212 | J5: ='# Customers'!J5/'# Customers'!$B5 -> 0.27040103 | ... AN5: ='# Customers'!AN5/'# Customers'!$B5 -> 0.069992474
A6: Q3-2013 | B6: 5719 | C6: ='# Customers'!C6/'# Customers'!$B6 -> 0.12886868 | D6: ='# Customers'!D6/'# Customers'!$B6 -> 0.13621262 | E6: ='# Customers'!E6/'# Customers'!$B6 -> 0.24147578 | F6: ='# Customers'!F6/'# Customers'!$B6 -> 0.18534709 | G6: ='# Customers'!G6/'# Customers'!$B6 -> 0.13254065 | H6: ='# Customers'!H6/'# Customers'!$B6 -> 0.13463892 | I6: ='# Customers'!I6/'# Customers'!$B6 -> 0.22311593 | J6: ='# Customers'!J6/'# Customers'!$B6 -> 0.18499738 | ... AM6: ='# Customers'!AM6/'# Customers'!$B6 -> 0.059101241
A7: Q4-2013 | B7: 3382 | C7: ='# Customers'!C7/'# Customers'!$B7 -> 0.12329982 | D7: ='# Customers'!D7/'# Customers'!$B7 -> 0.19810763 | E7: ='# Customers'!E7/'# Customers'!$B7 -> 0.16499113 | F7: ='# Customers'!F7/'# Customers'!$B7 -> 0.1306919 | G7: ='# Customers'!G7/'# Customers'!$B7 -> 0.12034299 | H7: ='# Customers'!H7/'# Customers'!$B7 -> 0.20697812 | I7: ='# Customers'!I7/'# Customers'!$B7 -> 0.17060911 | J7: ='# Customers'!J7/'# Customers'!$B7 -> 0.13926671 | ... AL7: ='# Customers'!AL7/'# Customers'!$B7 -> 0.055292726
A8: Q1-2014 | B8: 3059 | C8: ='# Customers'!C8/'# Customers'!$B8 -> 0.18666231 | D8: ='# Customers'!D8/'# Customers'!$B8 -> 0.13599215 | E8: ='# Customers'!E8/'# Customers'!$B8 -> 0.10591697 | F8: ='# Customers'!F8/'# Customers'!$B8 -> 0.10559006 | G8: ='# Customers'!G8/'# Customers'!$B8 -> 0.18077803 | H8: ='# Customers'!H8/'# Customers'!$B8 -> 0.15462569 | I8: ='# Customers'!I8/'# Customers'!$B8 -> 0.11310886 | J8: ='# Customers'!J8/'# Customers'!$B8 -> 0.11801242 | ... AK8: ='# Customers'!AK8/'# Customers'!$B8 -> 0.050343249
A9: Q2-2014 | B9: 5172 | C9: ='# Customers'!C9/'# Customers'!$B9 -> 0.12219644 | D9: ='# Customers'!D9/'# Customers'!$B9 -> 0.092034029 | E9: ='# Customers'!E9/'# Customers'!$B9 -> 0.084686775 | F9: ='# Customers'!F9/'# Customers'!$B9 -> 0.1620263 | G9: ='# Customers'!G9/'# Customers'!$B9 -> 0.12896365 | H9: ='# Customers'!H9/'# Customers'!$B9 -> 0.095320959 | I9: ='# Customers'!I9/'# Customers'!$B9 -> 0.10015468 | J9: ='# Customers'!J9/'# Customers'!$B9 -> 0.18078113 | ... AJ9: ='# Customers'!AJ9/'# Customers'!$B9 -> 0.040216551
A10: Q3-2014 | B10: 3074 | C10: ='# Customers'!C10/'# Customers'!$B10 -> 0.081001952 | D10: ='# Customers'!D10/'# Customers'!$B10 -> 0.07839948 | E10: ='# Customers'!E10/'# Customers'!$B10 -> 0.15289525 | F10: ='# Customers'!F10/'# Customers'!$B10 -> 0.1187378 | G10: ='# Customers'!G10/'# Customers'!$B10 -> 0.082953806 | H10: ='# Customers'!H10/'# Customers'!$B10 -> 0.081001952 | I10: ='# Customers'!I10/'# Customers'!$B10 -> 0.1584255 | J10: ='# Customers'!J10/'# Customers'!$B10 -> 0.11093038 | ... AI10: ='# Customers'!AI10/'# Customers'!$B10 -> 0.041639558
A11: Q4-2014 | B11: 1988 | C11: ='# Customers'!C11/'# Customers'!$B11 -> 0.091549296 | D11: ='# Customers'!D11/'# Customers'!$B11 -> 0.13279678 | E11: ='# Customers'!E11/'# Customers'!$B11 -> 0.10160966 | F11: ='# Customers'!F11/'# Customers'!$B11 -> 0.097082495 | G11: ='# Customers'!G11/'# Customers'!$B11 -> 0.076961771 | H11: ='# Customers'!H11/'# Customers'!$B11 -> 0.15241449 | I11: ='# Customers'!I11/'# Customers'!$B11 -> 0.11317907 | J11: ='# Customers'!J11/'# Customers'!$B11 -> 0.074949698 | ... AH11: ='# Customers'!AH11/'# Customers'!$B11 -> 0.033702213
A12: Q1-2015 | B12: 1747 | C12: ='# Customers'!C12/'# Customers'!$B12 -> 0.13337149 | D12: ='# Customers'!D12/'# Customers'!$B12 -> 0.10074413 | E12: ='# Customers'!E12/'# Customers'!$B12 -> 0.077275329 | F12: ='# Customers'!F12/'# Customers'!$B12 -> 0.07498569 | G12: ='# Customers'!G12/'# Customers'!$B12 -> 0.13108185 | H12: ='# Customers'!H12/'# Customers'!$B12 -> 0.10188895 | I12: ='# Customers'!I12/'# Customers'!$B12 -> 0.068116772 | J12: ='# Customers'!J12/'# Customers'!$B12 -> 0.076130509 | ... AG12: ='# Customers'!AG12/'# Customers'!$B12 -> 0.03606182
A13: Q2-2015 | B13: 3402 | C13: ='# Customers'!C13/'# Customers'!$B13 -> 0.093768372 | D13: ='# Customers'!D13/'# Customers'!$B13 -> 0.071134627 | E13: ='# Customers'!E13/'# Customers'!$B13 -> 0.06760729 | F13: ='# Customers'!F13/'# Customers'!$B13 -> 0.13109935 | G13: ='# Customers'!G13/'# Customers'!$B13 -> 0.094062316 | H13: ='# Customers'!H13/'# Customers'!$B13 -> 0.052910053 | I13: ='# Customers'!I13/'# Customers'!$B13 -> 0.060552616 | J13: ='# Customers'!J13/'# Customers'!$B13 -> 0.12727807 | ... AF13: ='# Customers'!AF13/'# Customers'!$B13 -> 0.030864198
A14: Q3-2015 | B14: 2295 | C14: ='# Customers'!C14/'# Customers'!$B14 -> 0.065359477 | D14: ='# Customers'!D14/'# Customers'!$B14 -> 0.059694989 | E14: ='# Customers'!E14/'# Customers'!$B14 -> 0.11938998 | F14: ='# Customers'!F14/'# Customers'!$B14 -> 0.095424837 | G14: ='# Customers'!G14/'# Customers'!$B14 -> 0.0583878 | H14: ='# Customers'!H14/'# Customers'!$B14 -> 0.064052288 | I14: ='# Customers'!I14/'# Customers'!$B14 -> 0.12374728 | J14: ='# Customers'!J14/'# Customers'!$B14 -> 0.091503268 | ... AE14: ='# Customers'!AE14/'# Customers'!$B14 -> 0.032679739
A15: Q4-2015 | B15: 1384 | C15: ='# Customers'!C15/'# Customers'!$B15 -> 0.055635838 | D15: ='# Customers'!D15/'# Customers'!$B15 -> 0.10260116 | E15: ='# Customers'!E15/'# Customers'!$B15 -> 0.077312139 | F15: ='# Customers'!F15/'# Customers'!$B15 -> 0.072254335 | G15: ='# Customers'!G15/'# Customers'!$B15 -> 0.067196532 | H15: ='# Customers'!H15/'# Customers'!$B15 -> 0.10693642 | I15: ='# Customers'!I15/'# Customers'!$B15 -> 0.083815029 | J15: ='# Customers'!J15/'# Customers'!$B15 -> 0.059971098 | ... AD15: ='# Customers'!AD15/'# Customers'!$B15 -> 0.026011561
A16: Q1-2016 | B16: 1295 | C16: ='# Customers'!C16/'# Customers'!$B16 -> 0.11428571 | D16: ='# Customers'!D16/'# Customers'!$B16 -> 0.077220077 | E16: ='# Customers'!E16/'# Customers'!$B16 -> 0.048648649 | F16: ='# Customers'!F16/'# Customers'!$B16 -> 0.052509653 | G16: ='# Customers'!G16/'# Customers'!$B16 -> 0.11274131 | H16: ='# Customers'!H16/'# Customers'!$B16 -> 0.085714286 | I16: ='# Customers'!I16/'# Customers'!$B16 -> 0.04015444 | J16: ='# Customers'!J16/'# Customers'!$B16 -> 0.062548263 | ... AC16: ='# Customers'!AC16/'# Customers'!$B16 -> 0.020849421
A17: Q2-2016 | B17: 2563 | C17: ='# Customers'!C17/'# Customers'!$B17 -> 0.088177917 | D17: ='# Customers'!D17/'# Customers'!$B17 -> 0.035895435 | E17: ='# Customers'!E17/'# Customers'!$B17 -> 0.046039797 | F17: ='# Customers'!F17/'# Customers'!$B17 -> 0.098322279 | G17: ='# Customers'!G17/'# Customers'!$B17 -> 0.062426844 | H17: ='# Customers'!H17/'# Customers'!$B17 -> 0.046820133 | I17: ='# Customers'!I17/'# Customers'!$B17 -> 0.037846274 | J17: ='# Customers'!J17/'# Customers'!$B17 -> 0.10495513 | ... AB17: ='# Customers'!AB17/'# Customers'!$B17 -> 0.02106906
A18: Q3-2016 | B18: 1585 | C18: ='# Customers'!C18/'# Customers'!$B18 -> 0.042271293 | D18: ='# Customers'!D18/'# Customers'!$B18 -> 0.035962145 | E18: ='# Customers'!E18/'# Customers'!$B18 -> 0.087066246 | F18: ='# Customers'!F18/'# Customers'!$B18 -> 0.059305994 | G18: ='# Customers'!G18/'# Customers'!$B18 -> 0.039116719 | H18: ='# Customers'!H18/'# Customers'!$B18 -> 0.035962145 | I18: ='# Customers'!I18/'# Customers'!$B18 -> 0.099053628 | J18: ='# Customers'!J18/'# Customers'!$B18 -> 0.05615142 | ... AA18: ='# Customers'!AA18/'# Customers'!$B18 -> 0.020820189
A19: Q4-2016 | B19: 949 | C19: ='# Customers'!C19/'# Customers'!$B19 -> 0.038988409 | D19: ='# Customers'!D19/'# Customers'!$B19 -> 0.076923077 | E19: ='# Customers'!E19/'# Customers'!$B19 -> 0.062170706 | F19: ='# Customers'!F19/'# Customers'!$B19 -> 0.051633298 | G19: ='# Customers'!G19/'# Customers'!$B19 -> 0.038988409 | H19: ='# Customers'!H19/'# Customers'!$B19 -> 0.095890411 | I19: ='# Customers'!I19/'# Customers'!$B19 -> 0.051633298 | J19: ='# Customers'!J19/'# Customers'!$B19 -> 0.030558483 | ... Z19: ='# Customers'!Z19/'# Customers'!$B19 -> 0.017913593
A20: Q1-2017 | B20: 886 | C20: ='# Customers'!C20/'# Customers'!$B20 -> 0.09255079 | D20: ='# Customers'!D20/'# Customers'!$B20 -> 0.056433409 | E20: ='# Customers'!E20/'# Customers'!$B20 -> 0.047404063 | F20: ='# Customers'!F20/'# Customers'!$B20 -> 0.041760722 | G20: ='# Customers'!G20/'# Customers'!$B20 -> 0.077878104 | H20: ='# Customers'!H20/'# Customers'!$B20 -> 0.073363431 | I20: ='# Customers'!I20/'# Customers'!$B20 -> 0.028216704 | J20: ='# Customers'!J20/'# Customers'!$B20 -> 0.028216704 | ... Y20: ='# Customers'!Y20/'# Customers'!$B20 -> 0.016930023
A21: Q2-2017 | B21: 1952 | C21: ='# Customers'!C21/'# Customers'!$B21 -> 0.054303279 | D21: ='# Customers'!D21/'# Customers'!$B21 -> 0.035348361 | E21: ='# Customers'!E21/'# Customers'!$B21 -> 0.037909836 | F21: ='# Customers'!F21/'# Customers'!$B21 -> 0.081454918 | G21: ='# Customers'!G21/'# Customers'!$B21 -> 0.047643443 | H21: ='# Customers'!H21/'# Customers'!$B21 -> 0.022028689 | I21: ='# Customers'!I21/'# Customers'!$B21 -> 0.022028689 | J21: ='# Customers'!J21/'# Customers'!$B21 -> 0.042008197 | ... X21: ='# Customers'!X21/'# Customers'!$B21 -> 0.012295082
A22: Q3-2017 | B22: 1228 | C22: ='# Customers'!C22/'# Customers'!$B22 -> 0.030130293 | D22: ='# Customers'!D22/'# Customers'!$B22 -> 0.031758958 | E22: ='# Customers'!E22/'# Customers'!$B22 -> 0.061074919 | F22: ='# Customers'!F22/'# Customers'!$B22 -> 0.040716612 | G22: ='# Customers'!G22/'# Customers'!$B22 -> 0.021172638 | H22: ='# Customers'!H22/'# Customers'!$B22 -> 0.023615635 | I22: ='# Customers'!I22/'# Customers'!$B22 -> 0.03990228 | J22: ='# Customers'!J22/'# Customers'!$B22 -> 0.034201954 | ... W22: ='# Customers'!W22/'# Customers'!$B22 -> 0.012214984
A23: Q4-2017 | B23: 723 | C23: ='# Customers'!C23/'# Customers'!$B23 -> 0.02351314 | D23: ='# Customers'!D23/'# Customers'!$B23 -> 0.081604426 | E23: ='# Customers'!E23/'# Customers'!$B23 -> 0.052558783 | F23: ='# Customers'!F23/'# Customers'!$B23 -> 0.01659751 | G23: ='# Customers'!G23/'# Customers'!$B23 -> 0.031811895 | H23: ='# Customers'!H23/'# Customers'!$B23 -> 0.041493776 | I23: ='# Customers'!I23/'# Customers'!$B23 -> 0.045643154 | J23: ='# Customers'!J23/'# Customers'!$B23 -> 0.024896266 | ... V23: ='# Customers'!V23/'# Customers'!$B23 -> 0.019363762
A24: Q1-2018 | B24: 734 | C24: ='# Customers'!C24/'# Customers'!$B24 -> 0.073569482 | D24: ='# Customers'!D24/'# Customers'!$B24 -> 0.054495913 | E24: ='# Customers'!E24/'# Customers'!$B24 -> 0.029972752 | F24: ='# Customers'!F24/'# Customers'!$B24 -> 0.020435967 | G24: ='# Customers'!G24/'# Customers'!$B24 -> 0.027247956 | H24: ='# Customers'!H24/'# Customers'!$B24 -> 0.034059946 | I24: ='# Customers'!I24/'# Customers'!$B24 -> 0.016348774 | J24: ='# Customers'!J24/'# Customers'!$B24 -> 0.020435967 | ... U24: ='# Customers'!U24/'# Customers'!$B24 -> 0.01226158
A25: Q2-2018 | B25: 1691 | C25: ='# Customers'!C25/'# Customers'!$B25 -> 0.048492017 | D25: ='# Customers'!D25/'# Customers'!$B25 -> 0.026611473 | E25: ='# Customers'!E25/'# Customers'!$B25 -> 0.026020106 | F25: ='# Customers'!F25/'# Customers'!$B25 -> 0.031933767 | G25: ='# Customers'!G25/'# Customers'!$B25 -> 0.024246008 | H25: ='# Customers'!H25/'# Customers'!$B25 -> 0.015966884 | I25: ='# Customers'!I25/'# Customers'!$B25 -> 0.018332348 | J25: ='# Customers'!J25/'# Customers'!$B25 -> 0.03903016 | ... T25: ='# Customers'!T25/'# Customers'!$B25 -> 0.013010053
A26: Q3-2018 | B26: 873 | C26: ='# Customers'!C26/'# Customers'!$B26 -> 0.018327606 | D26: ='# Customers'!D26/'# Customers'!$B26 -> 0.033218786 | E26: ='# Customers'!E26/'# Customers'!$B26 -> 0.041237113 | F26: ='# Customers'!F26/'# Customers'!$B26 -> 0.025200458 | G26: ='# Customers'!G26/'# Customers'!$B26 -> 0.021764032 | H26: ='# Customers'!H26/'# Customers'!$B26 -> 0.013745704 | I26: ='# Customers'!I26/'# Customers'!$B26 -> 0.028636884 | J26: ='# Customers'!J26/'# Customers'!$B26 -> 0.037800687 | ... S26: ='# Customers'!S26/'# Customers'!$B26 -> 0.017182131
A27: Q4-2018 | B27: 419 | C27: ='# Customers'!C27/'# Customers'!$B27 -> 0.016706444 | D27: ='# Customers'!D27/'# Customers'!$B27 -> 0.028639618 | E27: ='# Customers'!E27/'# Customers'!$B27 -> 0.023866348 | F27: ='# Customers'!F27/'# Customers'!$B27 -> 0.021479714 | G27: ='# Customers'!G27/'# Customers'!$B27 -> 0.0095465394 | H27: ='# Customers'!H27/'# Customers'!$B27 -> 0.026252983 | I27: ='# Customers'!I27/'# Customers'!$B27 -> 0.021479714 | J27: ='# Customers'!J27/'# Customers'!$B27 -> 0.0047732697 | ... R27: ='# Customers'!R27/'# Customers'!$B27 -> 0.0095465394
A28: Q1-2019 | B28: 423 | C28: ='# Customers'!C28/'# Customers'!$B28 -> 0.023640662 | D28: ='# Customers'!D28/'# Customers'!$B28 -> 0.026004728 | E28: ='# Customers'!E28/'# Customers'!$B28 -> 0.016548463 | F28: ='# Customers'!F28/'# Customers'!$B28 -> 0.016548463 | G28: ='# Customers'!G28/'# Customers'!$B28 -> 0.016548463 | H28: ='# Customers'!H28/'# Customers'!$B28 -> 0.026004728 | I28: ='# Customers'!I28/'# Customers'!$B28 -> 0.016548463 | J28: ='# Customers'!J28/'# Customers'!$B28 -> 0.021276596 | ... Q28: ='# Customers'!Q28/'# Customers'!$B28 -> 0.023640662
A29: Q2-2019 | B29: 652 | C29: ='# Customers'!C29/'# Customers'!$B29 -> 0.039877301 | D29: ='# Customers'!D29/'# Customers'!$B29 -> 0.0061349693 | E29: ='# Customers'!E29/'# Customers'!$B29 -> 0.013803681 | F29: ='# Customers'!F29/'# Customers'!$B29 -> 0.029141104 | G29: ='# Customers'!G29/'# Customers'!$B29 -> 0.021472393 | H29: ='# Customers'!H29/'# Customers'!$B29 -> 0.015337423 | I29: ='# Customers'!I29/'# Customers'!$B29 -> 0.01993865 | J29: ='# Customers'!J29/'# Customers'!$B29 -> 0.035276074 | ... P29: ='# Customers'!P29/'# Customers'!$B29 -> 0.009202454
A30: Q3-2019 | B30: 515 | C30: ='# Customers'!C30/'# Customers'!$B30 -> 0.011650485 | D30: ='# Customers'!D30/'# Customers'!$B30 -> 0.027184466 | E30: ='# Customers'!E30/'# Customers'!$B30 -> 0.021359223 | F30: ='# Customers'!F30/'# Customers'!$B30 -> 0.017475728 | G30: ='# Customers'!G30/'# Customers'!$B30 -> 0.013592233 | H30: ='# Customers'!H30/'# Customers'!$B30 -> 0.011650485 | I30: ='# Customers'!I30/'# Customers'!$B30 -> 0.034951456 | J30: ='# Customers'!J30/'# Customers'!$B30 -> 0.0097087379 | ... O30: ='# Customers'!O30/'# Customers'!$B30 -> 0.017475728
A31: Q4-2019 | B31: 308 | C31: ='# Customers'!C31/'# Customers'!$B31 -> 0.029220779 | D31: ='# Customers'!D31/'# Customers'!$B31 -> 0.032467532 | E31: ='# Customers'!E31/'# Customers'!$B31 -> 0.012987013 | F31: ='# Customers'!F31/'# Customers'!$B31 -> 0.012987013 | G31: ='# Customers'!G31/'# Customers'!$B31 -> 0.022727273 | H31: ='# Customers'!H31/'# Customers'!$B31 -> 0.019480519 | I31: ='# Customers'!I31/'# Customers'!$B31 -> 0.022727273 | J31: ='# Customers'!J31/'# Customers'!$B31 -> 0.022727273 | ... N31: ='# Customers'!N31/'# Customers'!$B31 -> 0.012987013
A32: Q1-2020 | B32: 304 | C32: ='# Customers'!C32/'# Customers'!$B32 -> 0.032894737 | D32: ='# Customers'!D32/'# Customers'!$B32 -> 0.0098684211 | E32: ='# Customers'!E32/'# Customers'!$B32 -> 0.023026316 | F32: ='# Customers'!F32/'# Customers'!$B32 -> 0.016447368 | G32: ='# Customers'!G32/'# Customers'!$B32 -> 0.019736842 | H32: ='# Customers'!H32/'# Customers'!$B32 -> 0.019736842 | I32: ='# Customers'!I32/'# Customers'!$B32 -> 0.026315789 | J32: ='# Customers'!J32/'# Customers'!$B32 -> 0.0098684211 | ... M32: ='# Customers'!M32/'# Customers'!$B32 -> 0.0065789474
A33: Q2-2020 | B33: 551 | C33: ='# Customers'!C33/'# Customers'!$B33 -> 0.029038113 | D33: ='# Customers'!D33/'# Customers'!$B33 -> 0.012704174 | E33: ='# Customers'!E33/'# Customers'!$B33 -> 0.01814882 | F33: ='# Customers'!F33/'# Customers'!$B33 -> 0.023593466 | G33: ='# Customers'!G33/'# Customers'!$B33 -> 0.019963702 | H33: ='# Customers'!H33/'# Customers'!$B33 -> 0.012704174 | I33: ='# Customers'!I33/'# Customers'!$B33 -> 0.016333938 | J33: ='# Customers'!J33/'# Customers'!$B33 -> 0.038112523 | ... L33: ='# Customers'!L33/'# Customers'!$B33 -> 0.0036297641
A34: Q3-2020 | B34: 408 | C34: ='# Customers'!C34/'# Customers'!$B34 -> 0.014705882 | D34: ='# Customers'!D34/'# Customers'!$B34 -> 0.0073529412 | E34: ='# Customers'!E34/'# Customers'!$B34 -> 0.026960784 | F34: ='# Customers'!F34/'# Customers'!$B34 -> 0.019607843 | G34: ='# Customers'!G34/'# Customers'!$B34 -> 0.0098039216 | H34: ='# Customers'!H34/'# Customers'!$B34 -> 0.022058824 | I34: ='# Customers'!I34/'# Customers'!$B34 -> 0.026960784 | J34: ='# Customers'!J34/'# Customers'!$B34 -> 0.017156863 | K34: ='# Customers'!K34/'# Customers'!$B34 -> 0.012254902
A35: Q4-2020 | B35: 237 | C35: ='# Customers'!C35/'# Customers'!$B35 -> 0.0084388186 | D35: ='# Customers'!D35/'# Customers'!$B35 -> 0.016877637 | E35: ='# Customers'!E35/'# Customers'!$B35 -> 0.021097046 | F35: ='# Customers'!F35/'# Customers'!$B35 -> 0.025316456 | G35: ='# Customers'!G35/'# Customers'!$B35 -> 0.012658228 | H35: ='# Customers'!H35/'# Customers'!$B35 -> 0.029535865 | I35: ='# Customers'!I35/'# Customers'!$B35 -> 0.037974684 | J35: ='# Customers'!J35/'# Customers'!$B35 -> 0.021097046
A36: Q1-2021 | B36: 278 | C36: ='# Customers'!C36/'# Customers'!$B36 -> 0.032374101 | D36: ='# Customers'!D36/'# Customers'!$B36 -> 0.017985612 | E36: ='# Customers'!E36/'# Customers'!$B36 -> 0.010791367 | F36: ='# Customers'!F36/'# Customers'!$B36 -> 0.021582734 | G36: ='# Customers'!G36/'# Customers'!$B36 -> 0.014388489 | H36: ='# Customers'!H36/'# Customers'!$B36 -> 0.017985612 | I36: ='# Customers'!I36/'# Customers'!$B36 -> 0.017985612
A37: Q2-2021 | B37: 518 | C37: ='# Customers'!C37/'# Customers'!$B37 -> 0.019305019 | D37: ='# Customers'!D37/'# Customers'!$B37 -> 0.017374517 | E37: ='# Customers'!E37/'# Customers'!$B37 -> 0.023166023 | F37: ='# Customers'!F37/'# Customers'!$B37 -> 0.019305019 | G37: ='# Customers'!G37/'# Customers'!$B37 -> 0.017374517 | H37: ='# Customers'!H37/'# Customers'!$B37 -> 0.013513514
A38: Q3-2021 | B38: 331 | C38: ='# Customers'!C38/'# Customers'!$B38 -> 0.01510574 | D38: ='# Customers'!D38/'# Customers'!$B38 -> 0.018126888 | E38: ='# Customers'!E38/'# Customers'!$B38 -> 0.033232628 | F38: ='# Customers'!F38/'# Customers'!$B38 -> 0.018126888 | G38: ='# Customers'!G38/'# Customers'!$B38 -> 0.0090634441
A39: Q4-2021 | B39: 213 | C39: ='# Customers'!C39/'# Customers'!$B39 -> 0.0093896714 | D39: ='# Customers'!D39/'# Customers'!$B39 -> 0.0093896714 | E39: ='# Customers'!E39/'# Customers'!$B39 -> 0.0093896714 | F39: ='# Customers'!F39/'# Customers'!$B39 -> 0.023474178
A40: Q1-2022 | B40: 302 | C40: ='# Customers'!C40/'# Customers'!$B40 -> 0.023178808 | D40: ='# Customers'!D40/'# Customers'!$B40 -> 0.01986755 | E40: ='# Customers'!E40/'# Customers'!$B40 -> 0.0033112583
...
